###try-catch语句
`try-catch`语法:

```javascript
try{
    //可能会导致错误的代码
}catch(error){
    //在错误发生时候怎么处理
}
```

如果`try`块中的任何代码发生错误,就会立即退出代码执行过程,然后接着执行`catch`块.此时,`catch`块会接收到一个包含错误信息的对象.与在其他语言不同的是,**_你可以不使用该错误对象,但你必须命名它._**该对象包含的实际信息会因浏览器而异,但共同的是有一个保存着错误消息的`message`属性和一个保存错误类型的`name`属性.

####finally子句
虽然`finally`子句在`try-catch`语句中是可选使用的,但是,`finally`子句一旦被使用,那么`finally`子句块中的代码总是要被执行的,不管`try`块中的代码是否是错误的

**_只要代码中包含`finally`子句,那么无论`try`还是`catch`语句块中的return语句都将被忽略._** 例子如下:

```javascript
function testFinally(){
    try{
        return 2
    }catch(error){
        return 1
    }finally{
        return 0
    }
}

console.log(testFinally()) //0
```

####错误类型
执行代码期间可能会发生的错误有多种类型.每种错误都有对应的错误类型,而当错误发生时,就会抛出相应类型的错误对象.ECMA-262定义了下列7种错误类型:

- Error
- EvalError
- RangeError
- ReferenceError
- SyntaxError
- TypeError
- URIError

`Error`是基类型,其他错误类型都继承自该类型.因此,所有错误类型共享了一组相同的属性(错误对象中的方法全是默认的对象方法).`Error`类型的错误很少见,如果有也是浏览器抛出的.该基类型的主要目的是供开发人员抛出自定义错误

`EvalError`类型的错误会在使用`eval()`函数而发生异常时被抛出.如果没有把`eval()`当成函数调用,就会抛出错误,例如:

```javascript
new eval() //抛出EvalError
eval = foo //抛出EvalError
```

`RangeError`类型的错误会在数值超出相应范围时触发.例如:

```javascript
var arr1 = new Array(-20) //抛出RangeError
var arr2 = new Array(Number.MAX_VALUE) //抛出RangeError
```

`ReferenceError`类型的错误会在找不到对象的情况下抛出(这种情况会直接导致`object expected`浏览器错误).通常在访问不存在的变量时,例如:

```javascript
var obj = x //抛出ReferenceError
```

`SyntaxError`,当`eval()`中的表达式或语句是不合法的,那么会抛出错误,例如:

```javascript
eval('a++b') //抛出SyntaxError
```

如果语法错误的代码出现在`eval()`函数之外,则不太可能使用`SyntaxError`,因为此时的语法错误会导致JS代码立即停止执行

`TypeError`类型在JS中会经常用到,在变量中保存着意外的类型时,或者在访问不存在的方法时,都会导致这种错误.错误原因多种多样,但归根结底还是由于执行特定于类型的操作时,变量的类型并不符合要求所致

```javascript
var o = new 10  //抛出TypeError
alert('name' in true)  //抛出TypeError
Function.prototype.toString.call('name') //抛出TypeError
```

在使用`encodeURI()`或`decodeURI()`,而URI格式不正确时,就会导致`URIError`错误.

####合理使用try-catch
使用`try-cache`最适合处理那些我们无法控制的错误.假设你在使用大型JS库中的函数,该函数可能会有意无意地抛出一些错误.由于我们不能修改这个库的源代码,所以大可将对该函数的调用放在`try-catch`语句中,万一有什么错误发生,也好恰当处理它们




